<?xml version="1.0" encoding="utf-8"?>
<!--
  OpenAMRobot differential-drive robot description.

  Link/joint geometry and STL meshes originate from a SolidWorks-exported URDF
  (sw_urdf_exporter, Stephen Brawner) by Niraj Dhakal (the upstream URDF author),
  later packaged by Raj Indulkar in openamrobot-simulation. See top-level
  NOTICE.md for the full attribution chain.

  Modifications applied in this revision (openamrobot-docking contribution):
    - added a base_footprint root link + base_joint (Nav2 TF convention)
    - symmetrised left/right wheel inertials (off-diagonals set to 0 and the
      two wheels made identical) — fixes the "robot circles when commanded
      straight" failure caused by SolidWorks-exported asymmetries
    - added camera_link and camera_rgb_optical_frame for AprilTag detection
    - lidar range adjusted to 0.15-12 m (see gazebo_control.xacro)
    - cylinder collisions on drive wheels with radius 0.10 m (reconciled
      with the DiffDrive plugin wheel_radius — see gazebo_control.xacro)
-->
<robot
  name="openamrobot" xmlns:xacro="http://www.ros.org/wiki/xacro">

  <!--
    base_footprint: ground-projection of base_link, Nav2 convention.
    base_joint lifts base_link 0.053467 m so the drive-wheel centres sit at
    z = wheel_radius = 0.10 m above the ground when base_footprint is at z=0.
  -->
  <link name="base_footprint"/>
  <joint name="base_joint" type="fixed">
    <origin xyz="0 0 0.053467" rpy="0 0 0"/>
    <parent link="base_footprint"/>
    <child link="base_link"/>
  </joint>

  <link
    name="base_link">
    <inertial>
      <origin
        xyz="0.0130206782008723 -0.0172284113080805 0.0788067724499705"
        rpy="0 0 0" />
      <mass
        value="4.17533781895232" />
      <inertia
        ixx="0.0556823489058236"
        ixy="1.55280027163122E-06"
        ixz="-7.03613595852389E-05"
        iyy="0.0914894501493208"
        iyz="2.61486872412502E-05"
        izz="0.135705995449285" />
    </inertial>
    <visual>
      <origin
        xyz="0 0 0"
        rpy="0 0 0" />
      <geometry>
        <mesh
          filename="package://openamrobot_description/meshes/visual/base_link.STL" />
      </geometry>
      <material
        name="">
        <color
          rgba="0.792156862745098 0.819607843137255 0.933333333333333 1" />
      </material>
    </visual>
    <collision>
      <origin
        xyz="0 0 0"
        rpy="0 0 0" />
      <geometry>
        <mesh
          filename="package://openamrobot_description/meshes/visual/base_link.STL" />
      </geometry>
    </collision>
  </link>
  <link
    name="fl_caster_link">
    <inertial>
      <origin
        xyz="-0.00137751441938117 1.75682554387491E-06 0.000943582234356817"
        rpy="0 0 0" />
      <mass
        value="0.0219398692551679" />
      <inertia
        ixx="5.47013223781611E-06"
        ixy="7.49140758780352E-10"
        ixz="-4.69358577988126E-07"
        iyy="5.29653308929842E-06"
        iyz="9.7174897982222E-10"
        izz="8.07647021403621E-06" />
    </inertial>
    <visual>
      <origin
        xyz="0 0 0"
        rpy="0 0 0" />
      <geometry>
        <mesh
          filename="package://openamrobot_description/meshes/visual/fl_caster_link.STL" />
      </geometry>
      <material
        name="">
        <color
          rgba="0.792156862745098 0.819607843137255 0.933333333333333 1" />
      </material>
    </visual>
    <collision>
      <origin
        xyz="0 0 0"
        rpy="0 0 0" />
      <geometry>
        <mesh
          filename="package://openamrobot_description/meshes/visual/fl_caster_link.STL" />
      </geometry>
    </collision>
  </link>
  <joint
    name="fl_caster_joint"
    type="fixed">
    <origin
      xyz="0.27505 0.215 -0.0093"
      rpy="0 0 0" />
    <parent
      link="base_link" />
    <child
      link="fl_caster_link" />
    <axis
      xyz="0 0 1" />
    <dynamics damping="0.001" friction="0.001" />

  </joint>
  <link
    name="fl_wheel_link">
    <inertial>
      <origin
        xyz="-6.39569062432788E-07 0.000112518782016985 0.00254643003871692"
        rpy="0 0 0" />
      <mass
        value="0.0267291642645555" />
      <inertia
        ixx="3.7398971674153E-06"
        ixy="-2.27443217252895E-10"
        ixz="6.56739699964409E-12"
        iyy="3.6803685469895E-06"
        iyz="-2.07598523671399E-11"
        izz="3.74071666197272E-06" />
    </inertial>
    <visual>
      <origin
        xyz="0 0 0"
        rpy="0 0 0" />
      <geometry>
        <mesh
          filename="package://openamrobot_description/meshes/visual/fl_wheel_link.STL" />
      </geometry>
      <material
        name="">
        <color
          rgba="0.792156862745098 0.819607843137255 0.933333333333333 1" />
      </material>
    </visual>
    <collision>
      <origin xyz="0 0 0" rpy="0 0 0"/>
      <geometry>
        <sphere radius="0.026"/>
      </geometry>
    </collision>
  </link>
  <joint
    name="fl_wheel_joint"
    type="fixed">
    <origin
      xyz="-0.015 0 -0.027746"
      rpy="0 0 0" />
    <parent
      link="fl_caster_link" />
    <child
      link="fl_wheel_link" />
    <axis
      xyz="0 1 0" />
    <dynamics damping="0.001" friction="0.001" />
  </joint>
  <link
    name="fr_caster_link">
    <inertial>
      <origin
        xyz="-0.001377514419381 1.75682554379164E-06 0.000943582234356991"
        rpy="0 0 0" />
      <mass
        value="0.0219398692551674" />
      <inertia
        ixx="5.47013223781604E-06"
        ixy="7.491407587617E-10"
        ixz="-4.69358577988093E-07"
        iyy="5.29653308929836E-06"
        iyz="9.71748979803426E-10"
        izz="8.07647021403615E-06" />
    </inertial>
    <visual>
      <origin
        xyz="0 0 0"
        rpy="0 0 0" />
      <geometry>
        <mesh
          filename="package://openamrobot_description/meshes/visual/fr_caster_link.STL" />
      </geometry>
      <material
        name="">
        <color
          rgba="0.792156862745098 0.819607843137255 0.933333333333333 1" />
      </material>
    </visual>
    <collision>
      <origin
        xyz="0 0 0"
        rpy="0 0 0" />
      <geometry>
        <mesh
          filename="package://openamrobot_description/meshes/visual/fr_caster_link.STL" />
      </geometry>
    </collision>
  </link>
  <joint
    name="fr_caster_joint"
    type="fixed">
    <origin
      xyz="0.27505 -0.215 -0.0093"
      rpy="0 0 0" />
    <parent
      link="base_link" />
    <child
      link="fr_caster_link" />
    <axis
      xyz="0 0 1" />
    <dynamics damping="0.001" friction="0.001" />

  </joint>
  <link
    name="fr_wheel_link">
    <inertial>
      <origin
        xyz="-7.06559357133152E-07 -5.5142527616292E-07 0.00254642490100031"
        rpy="0 0 0" />
      <mass
        value="0.0241949191842345" />
      <inertia
        ixx="3.24977626996243E-06"
        ixy="-2.27443225645868E-10"
        ixz="6.5668525167282E-12"
        iyy="3.65583795395343E-06"
        iyz="-2.07598384413479E-11"
        izz="3.25059576514846E-06" />
    </inertial>
    <visual>
      <origin
        xyz="0 0 0"
        rpy="0 0 0" />
      <geometry>
        <mesh
          filename="package://openamrobot_description/meshes/visual/fr_wheel_link.STL" />
      </geometry>
      <material
        name="">
        <color
          rgba="0.792156862745098 0.819607843137255 0.933333333333333 1" />
      </material>
    </visual>
    <collision>
      <origin xyz="0 0 0" rpy="0 0 0"/>
      <geometry>
        <sphere radius="0.026"/>
      </geometry>
    </collision>
  </link>
  <joint
    name="fr_wheel_joint"
    type="fixed">
    <origin
      xyz="-0.015 0 -0.027746"
      rpy="0 0 0" />
    <parent
      link="fr_caster_link" />
    <child
      link="fr_wheel_link" />
    <axis
      xyz="0 1 0" />
    <dynamics damping="0.001" friction="0.001" />
  </joint>
  <link
    name="br_caster_link">
    <inertial>
      <origin
        xyz="-0.001377514419381 1.7568255438194E-06 0.000943582234356914"
        rpy="0 0 0" />
      <mass
        value="0.0219398692551676" />
      <inertia
        ixx="5.47013223781607E-06"
        ixy="7.49140758766451E-10"
        ixz="-4.69358577988097E-07"
        iyy="5.29653308929839E-06"
        iyz="9.7174897977481E-10"
        izz="8.07647021403621E-06" />
    </inertial>
    <visual>
      <origin
        xyz="0 0 0"
        rpy="0 0 0" />
      <geometry>
        <mesh
          filename="package://openamrobot_description/meshes/visual/br_caster_link.STL" />
      </geometry>
      <material
        name="">
        <color
          rgba="0.792156862745098 0.819607843137255 0.933333333333333 1" />
      </material>
    </visual>
    <collision>
      <origin
        xyz="0 0 0"
        rpy="0 0 0" />
      <geometry>
        <mesh
          filename="package://openamrobot_description/meshes/visual/br_caster_link.STL" />
      </geometry>
    </collision>
  </link>
  <joint
    name="br_caster_joint"
    type="fixed">
    <origin
      xyz="-0.27495 -0.215 -0.0093"
      rpy="0 0 0" />
    <parent
      link="base_link" />
    <child
      link="br_caster_link" />
    <axis
      xyz="0 0 1" />
    <dynamics damping="0.001" friction="0.001" />

  </joint>
  <link
    name="br_wheel_link">
    <inertial>
      <origin
        xyz="-7.06559360075243E-07 -5.51425279493589E-07 0.0025464249010014"
        rpy="0 0 0" />
      <mass
        value="0.0241949191842423" />
      <inertia
        ixx="3.24977626996335E-06"
        ixy="-2.27443226363324E-10"
        ixz="6.56685281184266E-12"
        iyy="3.65583795395474E-06"
        iyz="-2.07598381632197E-11"
        izz="3.25059576515051E-06" />
    </inertial>
    <visual>
      <origin
        xyz="0 0 0"
        rpy="0 0 0" />
      <geometry>
        <mesh
          filename="package://openamrobot_description/meshes/visual/br_wheel_link.STL" />
      </geometry>
      <material
        name="">
        <color
          rgba="0.792156862745098 0.819607843137255 0.933333333333333 1" />
      </material>
    </visual>
    <collision>
      <origin xyz="0 0 0" rpy="0 0 0"/>
      <geometry>
        <sphere radius="0.026"/>
      </geometry>
    </collision>
  </link>
  <joint
    name="br_wheel_joint"
    type="fixed">
    <origin
      xyz="-0.015 0 -0.027746"
      rpy="0 0 0" />
    <parent
      link="br_caster_link" />
    <child
      link="br_wheel_link" />
    <axis
      xyz="0 1 0" />
    <dynamics damping="0.001" friction="0.001" />
  </joint>
  <link
    name="bl_caster_link">
    <inertial>
      <origin
        xyz="-0.00137751441938105 1.75682554365286E-06 0.000943582234356866"
        rpy="0 0 0" />
      <mass
        value="0.0219398692551676" />
      <inertia
        ixx="5.4701322378161E-06"
        ixy="7.49140758741953E-10"
        ixz="-4.69358577988104E-07"
        iyy="5.29653308929842E-06"
        iyz="9.71748979762017E-10"
        izz="8.07647021403621E-06" />
    </inertial>
    <visual>
      <origin
        xyz="0 0 0"
        rpy="0 0 0" />
      <geometry>
        <mesh
          filename="package://openamrobot_description/meshes/visual/bl_caster_link.STL" />
      </geometry>
      <material
        name="">
        <color
          rgba="0.792156862745098 0.819607843137255 0.933333333333333 1" />
      </material>
    </visual>
    <collision>
      <origin
        xyz="0 0 0"
        rpy="0 0 0" />
      <geometry>
        <mesh
          filename="package://openamrobot_description/meshes/visual/bl_caster_link.STL" />
      </geometry>
    </collision>
  </link>
  <joint
    name="bl_caster_joint"
    type="fixed">
    <origin
      xyz="-0.27495 0.215 -0.0093"
      rpy="0 0 0" />
    <parent
      link="base_link" />
    <child
      link="bl_caster_link" />
    <axis
      xyz="0 0 1" />
    <dynamics damping="0.001" friction="0.001" />

  </joint>
  <link
    name="bl_wheel_link">
    <inertial>
      <origin
        xyz="-7.06559361574044E-07 -5.51425277522943E-07 0.00254642490100057"
        rpy="0 0 0" />
      <mass
        value="0.0241949191842375" />
      <inertia
        ixx="3.24977626996275E-06"
        ixy="-2.27443226792169E-10"
        ixz="6.56685274690658E-12"
        iyy="3.65583795395393E-06"
        iyz="-2.07598383426284E-11"
        izz="3.25059576514932E-06" />
    </inertial>
    <visual>
      <origin
        xyz="0 0 0"
        rpy="0 0 0" />
      <geometry>
        <mesh
          filename="package://openamrobot_description/meshes/visual/bl_wheel_link.STL" />
      </geometry>
      <material
        name="">
        <color
          rgba="0.792156862745098 0.819607843137255 0.933333333333333 1" />
      </material>
    </visual>
    <collision>
      <origin xyz="0 0 0" rpy="0 0 0"/>
      <geometry>
        <sphere radius="0.026"/>
      </geometry>
    </collision>
  </link>
  <joint
    name="bl_wheel_joint"
    type="fixed">
    <origin
      xyz="-0.015 0 -0.027746"
      rpy="0 0 0" />
    <parent
      link="bl_caster_link" />
    <child
      link="bl_wheel_link" />
    <axis
      xyz="0 1 0" />
    <dynamics damping="0.001" friction="0.001" />
  </joint>

  <!--
    Drive wheels.

    Inertials made symmetric: off-diagonal terms zeroed and ixx = iyy = izz
    forced to the same average so left and right behave identically. The
    SolidWorks-exported per-wheel inertials had tiny (1e-8) off-diagonal
    asymmetries that made the robot curve when commanded straight in Gazebo.
  -->
  <link
    name="left_wheel_link">
    <inertial>
      <origin xyz="0 0 0" rpy="0 0 0" />
      <mass value="1.06112497715273" />
      <inertia
        ixx="0.003398197" ixy="0" ixz="0"
        iyy="0.006426349" iyz="0"
        izz="0.003397389" />
    </inertial>
    <visual>
      <origin
        xyz="0 0 0"
        rpy="0 0 0" />
      <geometry>
        <mesh
          filename="package://openamrobot_description/meshes/visual/left_wheel_link.STL" />
      </geometry>
      <material
        name="">
        <color
          rgba="0.792156862745098 0.819607843137255 0.933333333333333 1" />
      </material>
    </visual>
    <collision>
      <origin xyz="0 0 0" rpy="1.5707963 0 0"/>
      <geometry>
        <!-- 0.11 cylinder vs DiffDrive wheel_radius=0.10 gives ~1 cm of
             penetration into the ground plane, which ODE's contact solver
             uses to apply traction. Without that overlap the wheels merely
             touch the floor and the robot does not move. -->
        <cylinder radius="0.11" length="0.046"/>
      </geometry>
    </collision>
  </link>
  <joint
    name="left_wheel_joint"
    type="continuous">
    <origin
      xyz="4.7743E-05 0.20375 0.046533"
      rpy="0 0 0" />
    <parent
      link="base_link" />
    <child
      link="left_wheel_link" />
    <axis
      xyz="0 1 0" />
    <dynamics damping="0.001" friction="0.001" />
  </joint>
  <link
    name="right_wheel_link">
    <inertial>
      <origin xyz="0 0 0" rpy="0 0 0" />
      <mass value="1.06112497715273" />
      <inertia
        ixx="0.003398197" ixy="0" ixz="0"
        iyy="0.006426349" iyz="0"
        izz="0.003397389" />
    </inertial>
    <visual>
      <origin
        xyz="0 0 0"
        rpy="0 0 0" />
      <geometry>
        <mesh
          filename="package://openamrobot_description/meshes/visual/right_wheel_link.STL" />
      </geometry>
      <material
        name="">
        <color
          rgba="0.792156862745098 0.819607843137255 0.933333333333333 1" />
      </material>
    </visual>
    <collision>
      <origin xyz="0 0 0" rpy="1.5707963 0 0"/>
      <geometry>
        <!-- 0.11 cylinder vs DiffDrive wheel_radius=0.10 gives ~1 cm of
             penetration into the ground plane, which ODE's contact solver
             uses to apply traction. Without that overlap the wheels merely
             touch the floor and the robot does not move. -->
        <cylinder radius="0.11" length="0.046"/>
      </geometry>
    </collision>
  </link>
  <joint
    name="right_wheel_joint"
    type="continuous">
    <origin
      xyz="4.7657E-05 -0.20375 0.046533"
      rpy="0 0 0" />
    <parent
      link="base_link" />
    <child
      link="right_wheel_link" />
    <axis
      xyz="0 1 0" />
    <dynamics damping="0.001" friction="0.001" />
  </joint>
  <link
    name="lidar_link">
    <inertial>
      <origin
        xyz="-0.028276907815542 0.000919025220279201 -0.0114509307164145"
        rpy="0 0 0" />
      <mass
        value="0.167633664227307" />
      <inertia
        ixx="5.11992170336187E-05"
        ixy="4.49443876491344E-07"
        ixz="1.5052713226636E-07"
        iyy="5.97364216311163E-05"
        iyz="5.02504950673121E-08"
        izz="0.000100924865484583" />
    </inertial>
    <visual>
      <origin
        xyz="0 0 0"
        rpy="0 0 0" />
      <geometry>
        <mesh
          filename="package://openamrobot_description/meshes/visual/lidar_link.STL" />
      </geometry>
      <material
        name="">
        <color
          rgba="0.792156862745098 0.819607843137255 0.933333333333333 1" />
      </material>
    </visual>
    <collision>
      <origin
        xyz="0 0 0"
        rpy="0 0 0" />
      <geometry>
        <mesh
          filename="package://openamrobot_description/meshes/visual/lidar_link.STL" />
      </geometry>
    </collision>

  </link>


  <joint
    name="lidar_joint"
    type="fixed">
    <origin
      xyz="0.35135 -0.0010251 0.1683"
      rpy="0 0 0" />
    <parent
      link="base_link" />
    <child
      link="lidar_link" />
    <axis
      xyz="0 0 0" />
  </joint>

  <!--
    Camera links.

    camera_link is the physical camera frame (X forward, Y left, Z up).
    camera_rgb_optical_frame is its image-coordinate counterpart (X right,
    Y down, Z forward) — the convention apriltag_ros::solvePnP requires when
    computing the AprilTag pose. The rotation rpy="-1.5708 0 -1.5708" applied
    to the optical joint is the standard −π/2, 0, −π/2 mapping.
  -->
  <link name="camera_link"/>
  <joint name="camera_joint" type="fixed">
    <origin xyz="0.35 0 0.22" rpy="0 0 0"/>
    <parent link="base_link"/>
    <child link="camera_link"/>
  </joint>

  <link name="camera_rgb_optical_frame"/>
  <joint name="camera_optical_joint" type="fixed">
    <origin xyz="0 0 0" rpy="-1.5707963 0 -1.5707963"/>
    <parent link="camera_link"/>
    <child link="camera_rgb_optical_frame"/>
  </joint>

  <xacro:include filename="gazebo_control.xacro" />


</robot>
